Workbook

Sheet Historias y tareas
A1: Clave | B1: Tipo | C1: Resumen | D1: Épica | E1: Estado | F1: Sprint | G1: Responsable
A2: SCRUM-12 | B2: Historia | C2: Como administrador de plataforma, quiero que la base de datos impida el acceso a datos de otra empresa. | D2: Fundaciones y arquitectura | E2: Finalizado | F2: Sprint 2, Sprint 3 | G2: Manuel Jansen
A3: SCRUM-18 | B3: Historia | C3: Como administrador, quiero que el bot use mi propia clave de API y que quede cifrada, para controlar mi consumo sin exponer mi cuenta. | D3: Motor conversacional y agenta | E3: Finalizado | F3: Sprint 2 | G3: Exequiel Alvarado
A4: SCRUM-24 | B4: Historia | C4: Como administrador de empresa, quiero que el bot aprenda del contenido de mi sitio web, para no tener que copiar manualmente lo que ya está publicado. | D4: Ingesta y base de conocimiento | E4: Finalizado | F4: Sprint 2 | G4: Exequiel Alvarado
A5: SCRUM-29 | B5: Historia | C5: Como administrador de plataforma, quiero ver todos los ejecutivos de todas las empresas | D5: Administración de plataforma | E5: En curso | F5: Sprint 3 | G5: Diana Guerrero
A6: SCRUM-35 | B6: Historia | C6: Como usuario final del chat, quiero hablar con una persona cuando el bot no me resuelve | D6: Chat público y widget | E6: En curso | F6: Sprint 3 | G6: Cristian Jorquera
A7: SCRUM-42 | B7: Historia | C7: Como administrador de empresa, quiero subir mis documentos y ver en qué va su procesamiento. | D7: Gestión documental y preguntas frecuentes | E7: En curso | F7: Sprint 3 | G7: Diana Guerrero
A8: SCRUM-48 | B8: Historia | C8: modificar | D8: Administración de plataforma | E8: Por hacer | F8: Sin sprint | G8: Manuel Jansen
A9: SCRUM-53 | B9: Historia | C9: Como usuario final del chat, quiero recibir respuestas basadas exclusivamente en la documentación de la empresa, para poder confiar en lo que el bot me dice. | D9: Motor conversacional y agenta | E9: Finalizado | F9: Sprint 2 | G9: Exequiel Alvarado
A10: SCRUM-59 | B10: Historia | C10: Como usuario final del chat, quiero que mi consulta quede registrada cuando no hay nadie disponible, para recibir respuesta después en vez de quedarme sin solución. | D10: Tiketera | E10: En curso | F10: Sin sprint | G10: Cristian Jorquera
A11: SCRUM-73 | B11: Historia | C11: Modelo de datos multi-tenant y migraciones | D11: Fundaciones y arquitectura | E11: Finalizado | F11: Sprint 1 | G11: Manuel Jansen
A12: SCRUM-79 | B12: Historia | C12: Autenticación con roles y sesión renovable | D12: Fundaciones y arquitectura | E12: Finalizado | F12: Sprint 1 | G12: Cristian Jorquera
... A56: SCRUM-189 | B56: Tarea | C56: WellQ: alinear FAQ y documentos con su negocio real | D56: Sin épica | E56: En revisión | F56: Sin sprint | G56: Exequiel Alvarado

Sheet Resumen
A1: Backlog de Jira · proyecto SCRUM («Chat-bot»)
A2: Fuente: exportación de Jira del 16-10-2026 (historias-jira.csv): historias y tareas; no incluye épicas ni subtareas. Todas las cifras son fórmulas COUNTIF/COUNTIFS sobre la hoja «Historias y tareas».
A4: Por estado
A5: Estado | B5: Cantidad | C5: % del total
A6: Finalizado | B6: =COUNTIF('Historias y tareas'!$E$2:$E$56,$A6) -> 21 | C6: =IF($B$10=0,0,B6/$B$10) -> 0.38181818
A7: En revisión | B7: =COUNTIF('Historias y tareas'!$E$2:$E$56,$A7) -> 11 | C7: =IF($B$10=0,0,B7/$B$10) -> 0.2
A8: En curso | B8: =COUNTIF('Historias y tareas'!$E$2:$E$56,$A8) -> 9 | C8: =IF($B$10=0,0,B8/$B$10) -> 0.16363636
A9: Por hacer | B9: =COUNTIF('Historias y tareas'!$E$2:$E$56,$A9) -> 14 | C9: =IF($B$10=0,0,B9/$B$10) -> 0.25454545
A10: Total historias y tareas | B10: =COUNTA('Historias y tareas'!$A$2:$A$56) -> 55 | C10: =SUM(C6:C9) -> 1
A12: Por tipo
A13: Tipo | B13: Total | C13: Finalizado | D13: En revisión | E13: En curso | F13: Por hacer
A14: Historia | B14: =COUNTIF('Historias y tareas'!$B$2:$B$56,$A14) -> 37 | C14: =COUNTIFS('Historias y tareas'!$B$2:$B$56,$A14,'Historias y tareas'!$E$2:$E$56,C$13) -> 15 | D14: =COUNTIFS('Historias y tareas'!$B$2:$B$56,$A14,'Historias y tareas'!$E$2:$E$56,D$13) -> 2 | E14: =COUNTIFS('Historias y tareas'!$B$2:$B$56,$A14,'Historias y tareas'!$E$2:$E$56,E$13) -> 9 | F14: =COUNTIFS('Historias y tareas'!$B$2:$B$56,$A14,'Historias y tareas'!$E$2:$E$56,F$13) -> 11
A15: Tarea | B15: =COUNTIF('Historias y tareas'!$B$2:$B$56,$A15) -> 18 | C15: =COUNTIFS('Historias y tareas'!$B$2:$B$56,$A15,'Historias y tareas'!$E$2:$E$56,C$13) -> 6 | D15: =COUNTIFS('Historias y tareas'!$B$2:$B$56,$A15,'Historias y tareas'!$E$2:$E$56,D$13) -> 9 | E15: =COUNTIFS('Historias y tareas'!$B$2:$B$56,$A15,'Historias y tareas'!$E$2:$E$56,E$13) -> 0 | F15: =COUNTIFS('Historias y tareas'!$B$2:$B$56,$A15,'Historias y tareas'!$E$2:$E$56,F$13) -> 3
A16: Total | B16: =SUM(B14:B15) -> 55 | C16: =SUM(C14:C15) -> 21 | D16: =SUM(D14:D15) -> 11 | E16: =SUM(E14:E15) -> 9 | F16: =SUM(F14:F15) -> 14
A18: Por sprint
A19: Sprint | B19: Total | C19: Finalizado | D19: En revisión | E19: En curso | F19: Por hacer
A20: Sprint 1 | B20: =COUNTIF('Historias y tareas'!$F$2:$F$56,"*"&$A20&"*") -> 7 | C20: =COUNTIFS('Historias y tareas'!$F$2:$F$56,"*"&$A20&"*",'Historias y tareas'!$E$2:$E$56,C$19) -> 7 | D20: =COUNTIFS('Historias y tareas'!$F$2:$F$56,"*"&$A20&"*",'Historias y tareas'!$E$2:$E$56,D$19) -> 0 | E20: =COUNTIFS('Historias y tareas'!$F$2:$F$56,"*"&$A20&"*",'Historias y tareas'!$E$2:$E$56,E$19) -> 0 | F20: =COUNTIFS('Historias y tareas'!$F$2:$F$56,"*"&$A20&"*",'Historias y tareas'!$E$2:$E$56,F$19) -> 0
A21: Sprint 2 | B21: =COUNTIF('Historias y tareas'!$F$2:$F$56,"*"&$A21&"*") -> 5 | C21: =COUNTIFS('Historias y tareas'!$F$2:$F$56,"*"&$A21&"*",'Historias y tareas'!$E$2:$E$56,C$19) -> 5 | D21: =COUNTIFS('Historias y tareas'!$F$2:$F$56,"*"&$A21&"*",'Historias y tareas'!$E$2:$E$56,D$19) -> 0 | E21: =COUNTIFS('Historias y tareas'!$F$2:$F$56,"*"&$A21&"*",'Historias y tareas'!$E$2:$E$56,E$19) -> 0 | F21: =COUNTIFS('Historias y tareas'!$F$2:$F$56,"*"&$A21&"*",'Historias y tareas'!$E$2:$E$56,F$19) -> 0
A22: Sprint 3 | B22: =COUNTIF('Historias y tareas'!$F$2:$F$56,"*"&$A22&"*") -> 9 | C22: =COUNTIFS('Historias y tareas'!$F$2:$F$56,"*"&$A22&"*",'Historias y tareas'!$E$2:$E$56,C$19) -> 3 | D22: =COUNTIFS('Historias y tareas'!$F$2:$F$56,"*"&$A22&"*",'Historias y tareas'!$E$2:$E$56,D$19) -> 0 | E22: =COUNTIFS('Historias y tareas'!$F$2:$F$56,"*"&$A22&"*",'Historias y tareas'!$E$2:$E$56,E$19) -> 5 | F22: =COUNTIFS('Historias y tareas'!$F$2:$F$56,"*"&$A22&"*",'Historias y tareas'!$E$2:$E$56,F$19) -> 1
A23: Sin sprint | B23: =COUNTIF('Historias y tareas'!$F$2:$F$56,"*"&$A23&"*") -> 35 | C23: =COUNTIFS('Historias y tareas'!$F$2:$F$56,"*"&$A23&"*",'Historias y tareas'!$E$2:$E$56,C$19) -> 7 | D23: =COUNTIFS('Historias y tareas'!$F$2:$F$56,"*"&$A23&"*",'Historias y tareas'!$E$2:$E$56,D$19) -> 11 | E23: =COUNTIFS('Historias y tareas'!$F$2:$F$56,"*"&$A23&"*",'Historias y tareas'!$E$2:$E$56,E$19) -> 4 | F23: =COUNTIFS('Historias y tareas'!$F$2:$F$56,"*"&$A23&"*",'Historias y tareas'!$E$2:$E$56,F$19) -> 13
A24: Total | B24: =SUM(B20:B23) -> 56 | C24: =SUM(C20:C23) -> 22 | D24: =SUM(D20:D23) -> 11 | E24: =SUM(E20:E23) -> 9 | F24: =SUM(F20:F23) -> 14
A25: Una incidencia que pasó por más de un sprint cuenta en cada uno (SCRUM-12); por eso el total de esta tabla puede superar el de historias y tareas.
A27: Por responsable
A28: Responsable | B28: Total | C28: Finalizado | D28: En revisión | E28: En curso | F28: Por hacer
A29: Exequiel Alvarado | B29: =COUNTIF('Historias y tareas'!$G$2:$G$56,$A29) -> 24 | C29: =COUNTIFS('Historias y tareas'!$G$2:$G$56,$A29,'Historias y tareas'!$E$2:$E$56,C$28) -> 12 | D29: =COUNTIFS('Historias y tareas'!$G$2:$G$56,$A29,'Historias y tareas'!$E$2:$E$56,D$28) -> 11 | E29: =COUNTIFS('Historias y tareas'!$G$2:$G$56,$A29,'Historias y tareas'!$E$2:$E$56,E$28) -> 1 | F29: =COUNTIFS('Historias y tareas'!$G$2:$G$56,$A29,'Historias y tareas'!$E$2:$E$56,F$28) -> 0
A30: Diana Guerrero | B30: =COUNTIF('Historias y tareas'!$G$2:$G$56,$A30) -> 20 | C30: =COUNTIFS('Historias y tareas'!$G$2:$G$56,$A30,'Historias y tareas'!$E$2:$E$56,C$28) -> 4 | D30: =COUNTIFS('Historias y tareas'!$G$2:$G$56,$A30,'Historias y tareas'!$E$2:$E$56,D$28) -> 0 | E30: =COUNTIFS('Historias y tareas'!$G$2:$G$56,$A30,'Historias y tareas'!$E$2:$E$56,E$28) -> 5 | F30: =COUNTIFS('Historias y tareas'!$G$2:$G$56,$A30,'Historias y tareas'!$E$2:$E$56,F$28) -> 11
A31: Cristian Jorquera | B31: =COUNTIF('Historias y tareas'!$G$2:$G$56,$A31) -> 6 | C31: =COUNTIFS('Historias y tareas'!$G$2:$G$56,$A31,'Historias y tareas'!$E$2:$E$56,C$28) -> 2 | D31: =COUNTIFS('Historias y tareas'!$G$2:$G$56,$A31,'Historias y tareas'!$E$2:$E$56,D$28) -> 0 | E31: =COUNTIFS('Historias y tareas'!$G$2:$G$56,$A31,'Historias y tareas'!$E$2:$E$56,E$28) -> 3 | F31: =COUNTIFS('Historias y tareas'!$G$2:$G$56,$A31,'Historias y tareas'!$E$2:$E$56,F$28) -> 1
A32: Manuel Jansen | B32: =COUNTIF('Historias y tareas'!$G$2:$G$56,$A32) -> 5 | C32: =COUNTIFS('Historias y tareas'!$G$2:$G$56,$A32,'Historias y tareas'!$E$2:$E$56,C$28) -> 3 | D32: =COUNTIFS('Historias y tareas'!$G$2:$G$56,$A32,'Historias y tareas'!$E$2:$E$56,D$28) -> 0 | E32: =COUNTIFS('Historias y tareas'!$G$2:$G$56,$A32,'Historias y tareas'!$E$2:$E$56,E$28) -> 0 | F32: =COUNTIFS('Historias y tareas'!$G$2:$G$56,$A32,'Historias y tareas'!$E$2:$E$56,F$28) -> 2
A33: Total | B33: =SUM(B29:B32) -> 55 | C33: =SUM(C29:C32) -> 21 | D33: =SUM(D29:D32) -> 11 | E33: =SUM(E29:E32) -> 9 | F33: =SUM(F29:F32) -> 14
A35: Por épica
A36: Épica | B36: Total | C36: Finalizado | D36: En revisión | E36: En curso | F36: Por hacer
A37: Administración de plataforma | B37: =COUNTIF('Historias y tareas'!$D$2:$D$56,$A37) -> 5 | C37: =COUNTIFS('Historias y tareas'!$D$2:$D$56,$A37,'Historias y tareas'!$E$2:$E$56,C$36) -> 3 | D37: =COUNTIFS('Historias y tareas'!$D$2:$D$56,$A37,'Historias y tareas'!$E$2:$E$56,D$36) -> 0 | E37: =COUNTIFS('Historias y tareas'!$D$2:$D$56,$A37,'Historias y tareas'!$E$2:$E$56,E$36) -> 1 | F37: =COUNTIFS('Historias y tareas'!$D$2:$D$56,$A37,'Historias y tareas'!$E$2:$E$56,F$36) -> 1
A38: Chat público y widget | B38: =COUNTIF('Historias y tareas'!$D$2:$D$56,$A38) -> 4 | C38: =COUNTIFS('Historias y tareas'!$D$2:$D$56,$A38,'Historias y tareas'!$E$2:$E$56,C$36) -> 2 | D38: =COUNTIFS('Historias y tareas'!$D$2:$D$56,$A38,'Historias y tareas'!$E$2:$E$56,D$36) -> 0 | E38: =COUNTIFS('Historias y tareas'!$D$2:$D$56,$A38,'Historias y tareas'!$E$2:$E$56,E$36) -> 1 | F38: =COUNTIFS('Historias y tareas'!$D$2:$D$56,$A38,'Historias y tareas'!$E$2:$E$56,F$36) -> 1
A39: Fundaciones y arquitectura | B39: =COUNTIF('Historias y tareas'!$D$2:$D$56,$A39) -> 4 | C39: =COUNTIFS('Historias y tareas'!$D$2:$D$56,$A39,'Historias y tareas'!$E$2:$E$56,C$36) -> 4 | D39: =COUNTIFS('Historias y tareas'!$D$2:$D$56,$A39,'Historias y tareas'!$E$2:$E$56,D$36) -> 0 | E39: =COUNTIFS('Historias y tareas'!$D$2:$D$56,$A39,'Historias y tareas'!$E$2:$E$56,E$36) -> 0 | F39: =COUNTIFS('Historias y tareas'!$D$2:$D$56,$A39,'Historias y tareas'!$E$2:$E$56,F$36) -> 0
A40: Ingesta y base de conocimiento | B40: =COUNTIF('Historias y tareas'!$D$2:$D$56,$A40) -> 4 | C40: =COUNTIFS('Historias y tareas'!$D$2:$D$56,$A40,'Historias y tareas'!$E$2:$E$56,C$36) -> 3 | D40: =COUNTIFS('Historias y tareas'!$D$2:$D$56,$A40,'Historias y tareas'!$E$2:$E$56,D$36) -> 0 | E40: =COUNTIFS('Historias y tareas'!$D$2:$D$56,$A40,'Historias y tareas'!$E$2:$E$56,E$36) -> 1 | F40: =COUNTIFS('Historias y tareas'!$D$2:$D$56,$A40,'Historias y tareas'!$E$2:$E$56,F$36) -> 0
A41: Motor conversacional y agenta | B41: =COUNTIF('Historias y tareas'!$D$2:$D$56,$A41) -> 4 | C41: =COUNTIFS('Historias y tareas'!$D$2:$D$56,$A41,'Historias y tareas'!$E$2:$E$56,C$36) -> 4 | D41: =COUNTIFS('Historias y tareas'!$D$2:$D$56,$A41,'Historias y tareas'!$E$2:$E$56,D$36) -> 0 | E41: =COUNTIFS('Historias y tareas'!$D$2:$D$56,$A41,'Historias y tareas'!$E$2:$E$56,E$36) -> 0 | F41: =COUNTIFS('Historias y tareas'!$D$2:$D$56,$A41,'Historias y tareas'!$E$2:$E$56,F$36) -> 0
A42: Derivación y consola de ejecutivo | B42: =COUNTIF('Historias y tareas'!$D$2:$D$56,$A42) -> 2 | C42: =COUNTIFS('Historias y tareas'!$D$2:$D$56,$A42,'Historias y tareas'!$E$2:$E$56,C$36) -> 0 | D42: =COUNTIFS('Historias y tareas'!$D$2:$D$56,$A42,'Historias y tareas'!$E$2:$E$56,D$36) -> 0 | E42: =COUNTIFS('Historias y tareas'!$D$2:$D$56,$A42,'Historias y tareas'!$E$2:$E$56,E$36) -> 1 | F42: =COUNTIFS('Historias y tareas'!$D$2:$D$56,$A42,'Historias y tareas'!$E$2:$E$56,F$36) -> 1
A43: Experiencia transversal | B43: =COUNTIF('Historias y tareas'!$D$2:$D$56,$A43) -> 1 | C43: =COUNTIFS('Historias y tareas'!$D$2:$D$56,$A43,'Historias y tareas'!$E$2:$E$56,C$36) -> 1 | D43: =COUNTIFS('Historias y tareas'!$D$2:$D$56,$A43,'Historias y tareas'!$E$2:$E$56,D$36) -> 0 | E43: =COUNTIFS('Historias y tareas'!$D$2:$D$56,$A43,'Historias y tareas'!$E$2:$E$56,E$36) -> 0 | F43: =COUNTIFS('Historias y tareas'!$D$2:$D$56,$A43,'Historias y tareas'!$E$2:$E$56,F$36) -> 0
A44: Gestión documental y preguntas frecuentes | B44: =COUNTIF('Historias y tareas'!$D$2:$D$56,$A44) -> 1 | C44: =COUNTIFS('Historias y tareas'!$D$2:$D$56,$A44,'Historias y tareas'!$E$2:$E$56,C$36) -> 0 | D44: =COUNTIFS('Historias y tareas'!$D$2:$D$56,$A44,'Historias y tareas'!$E$2:$E$56,D$36) -> 0 | E44: =COUNTIFS('Historias y tareas'!$D$2:$D$56,$A44,'Historias y tareas'!$E$2:$E$56,E$36) -> 1 | F44: =COUNTIFS('Historias y tareas'!$D$2:$D$56,$A44,'Historias y tareas'!$E$2:$E$56,F$36) -> 0
A45: Tiketera | B45: =COUNTIF('Historias y tareas'!$D$2:$D$56,$A45) -> 1 | C45: =COUNTIFS('Historias y tareas'!$D$2:$D$56,$A45,'Historias y tareas'!$E$2:$E$56,C$36) -> 0 | D45: =COUNTIFS('Historias y tareas'!$D$2:$D$56,$A45,'Historias y tareas'!$E$2:$E$56,D$36) -> 0 | E45: =COUNTIFS('Historias y tareas'!$D$2:$D$56,$A45,'Historias y tareas'!$E$2:$E$56,E$36) -> 1 | F45: =COUNTIFS('Historias y tareas'!$D$2:$D$56,$A45,'Historias y tareas'!$E$2:$E$56,F$36) -> 0
...
